Workbook

Sheet Instructions
A1: MS Excel Practical Exam
A2: Total Questions: 30
A3: Difficulty Level: Medium
A4: Syllabus: Formulas, Logical Functions, Lookups, INDEX-MATCH, Pivot Tables & Charts, Data Analysis
A5: Attempt all questions using appropriate Excel tools/functions.

Sheet Sales_Data
A1: Order_ID | B1: Region | C1: Salesperson | D1: Product | E1: Quantity | F1: Unit_Price | G1: Sales_Date | I1: Total Sales | J1: GST | K1: Final Amount Payable
A2: 301 | B2: North | C2: Amit | D2: Laptop | E2: 2 | F2: 45000 | G2: 05-01-2025 | I2: =Sales_Data!E2*Sales_Data!F2 -> 90000 | J2: =VLOOKUP(D2,Product_Master!A1:C4,3,0) -> 18 | K2: =I2+(J2% * I2) -> 106200
A3: 302 | B3: South | C3: Riya | D3: Mobile | E3: 5 | F3: 15000 | G3: 07-01-2025 | I3: =Sales_Data!E3*Sales_Data!F3 -> 75000 | J3: =VLOOKUP(D3,Product_Master!A2:C5,3,0) -> 12 | K3: =I3+(J3% * I3) -> 84000
A4: 303 | B4: East | C4: Kunal | D4: Tablet | E4: 3 | F4: 18000 | G4: 10-01-2025 | I4: =Sales_Data!E4*Sales_Data!F4 -> 54000 | J4: =VLOOKUP(D4,Product_Master!A3:C6,3,0) -> 12 | K4: =I4+(J4% * I4) -> 60480
A5: 304 | B5: West | C5: Neha | D5: Laptop | E5: 1 | F5: 45000 | G5: 12-01-2025 | I5: =Sales_Data!E5*Sales_Data!F5 -> 45000 | J5: =VLOOKUP(D5,Product_Master!A1:C4,3,0) -> 18 | K5: =I5+(J5% * I5) -> 53100
A6: 305 | B6: North | C6: Amit | D6: Mobile | E6: 4 | F6: 15000 | G6: 15-01-2025 | I6: =Sales_Data!E6*Sales_Data!F6 -> 60000 | J6: =VLOOKUP(D6,Product_Master!A2:C5,3,0) -> 12 | K6: =I6+(J6% * I6) -> 67200
A7: 306 | B7: South | C7: Riya | D7: Laptop | E7: 2 | F7: 45000 | G7: 18-01-2025 | I7: =Sales_Data!E7*Sales_Data!F7 -> 90000 | J7: =VLOOKUP(D7,Product_Master!A1:C4,3,0) -> 18 | K7: =I7+(J7% * I7) -> 106200
J8: Grand Total : | K8: =SUM(K2:K7) -> 477180

Sheet Product_Master
A1: Product | B1: Category | C1: GST_%
A2: Laptop | B2: Electronics | C2: 18
A3: Mobile | B3: Electronics | C3: 12
A4: Tablet | B4: Electronics | C4: 12

Sheet Sheet1
A1: Row Labels | B1: Sum of Unit_Price
A2: Laptop | B2: 135000
A3: Mobile | B3: 30000
A4: Tablet | B4: 18000
A5: Grand Total | B5: 183000 | E5: Row Labels | F5: Sum of Unit_Price
E6: East | F6: 18000
E7: West | F7: 45000
E8: South | F8: 60000
E9: North | F9: 60000
E10: Grand Total | F10: 183000

Sheet Sheet2

Sheet Student_Marks
A1: Student_ID | B1: Name | C1: Maths | D1: Statistics | E1: Excel | F1: Attendance_%
A2: 1 | B2: Rahul | C2: 78 | D2: 82 | E2: 85 | F2: 92
A3: 2 | B3: Sneha | C3: 88 | D3: 91 | E3: 90 | F3: 96
A4: 3 | B4: Arjun | C4: 65 | D4: 70 | E4: 72 | F4: 85
A5: 4 | B5: Pooja | C5: 92 | D5: 89 | E5: 94 | F5: 98
A6: 5 | B6: Vikas | C6: 55 | D6: 60 | E6: 58 | F6: 80

Sheet Questions
A1: 1. Calculate Total Sales for each order (Quantity × Unit_Price). | J1: 2
A2: 2. Calculate GST Amount using VLOOKUP from Product_Master. | J2: 2
A3: 3. Find Final Amount payable (Total Sales + GST). | J3: 2
A4: 4. Find Grand Total of Final Amount. | J4: 2
A5: 5. Count total number of orders using COUNTA. | J5: 2
A6: 6. Find Region-wise total sales using SUMIF. | J6: 2
A7: 7. Use IF to classify Quantity as High (>3) or Low (<=3). | J7: 2
A8: 8. Find the maximum and minimum Final Amount. | J8: 2
A9: 9. Extract month name from Sales_Date. | J9: 2
A10: 10. Sort Sales_Data by Final Amount (Descending). | J10: 2
A11: 11. Use INDEX-MATCH to fetch Product Category. | J11: 2
A12: 12. Calculate average marks of each student. | J12: 2
... A30: 30. Protect the Student_Marks sheet. | J30: 2
J32: =SUM(J1:J30) -> 60

Sheet Answers
A1: Ans-1
B2: Total Sales
B3: =Sales_Data!E2*Sales_Data!F2 -> 90000
B4: =Sales_Data!E3*Sales_Data!F3 -> 75000
B5: =Sales_Data!E4*Sales_Data!F4 -> 54000
B6: =Sales_Data!E5*Sales_Data!F5 -> 45000
B7: =Sales_Data!E6*Sales_Data!F6 -> 60000
B8: =Sales_Data!E7*Sales_Data!F7 -> 90000
A10: Ans-2
B11: GST
A12: Laptop | B12: =VLOOKUP(A12,Product_Master!A1:C4,3,0) -> 18
A15: Ans-3
B16: Final Amount Payable (Total Sales + GST)
B17: =Sales_Data!K2 -> 106200
B18: =Sales_Data!K3 -> 84000
B19: =Sales_Data!K4 -> 60480
B20: =Sales_Data!K5 -> 53100
B21: =Sales_Data!K6 -> 67200
B22: =Sales_Data!K7 -> 106200
A25: Ans-4
B26: Grand Total of Final Amount Payable
B27: =SUM(B17:B22) -> 477180
A30: Ans-5
B31: =COUNTA(Sales_Data!A2:A7) -> 6
A34: Ans-6
B35: Region | C35: Total Sales
B36: North
B37: South
B38: East
B39: West
A41: Ans-7 | B41: Max | C41: Min
B42: =MAX(B3:B8) -> 90000 | C42: =MIN(B3:B8) -> 45000
A46: Ans-12 | B46: Student_ID | C46: Name | D46: Maths | E46: Statistics | F46: Excel | G46: Attendance_% | I46: Average
B47: 1 | C47: Rahul | D47: 78 | E47: 82 | F47: 85 | G47: 92 | I47: =AVERAGE(D47:F47) -> 81.666667
B48: 2 | C48: Sneha | D48: 88 | E48: 91 | F48: 90 | G48: 96 | I48: =AVERAGE(D48:F48) -> 89.666667
B49: 3 | C49: Arjun | D49: 65 | E49: 70 | F49: 72 | G49: 85 | I49: =AVERAGE(D49:F49) -> 69
B50: 4 | C50: Pooja | D50: 92 | E50: 89 | F50: 94 | G50: 98 | I50: =AVERAGE(D50:F50) -> 91.666667
B51: 5 | C51: Vikas | D51: 55 | E51: 60 | F51: 58 | G51: 80 | I51: =AVERAGE(D51:F51) -> 57.666667
A55: Ans-13 | B55: =MAX(I47:I51) -> 91.666667
A58: Ans-16
...
